Workbook

Sheet 成绩单
B2: 2014年中国技能大赛—第43届世界技能大赛数控铣项目全国选拔赛样题评分汇总表
B4: 单位（学校） | G4: 选手编号
B5: 选手姓名
B7: 评判项目编码 | D7: 评判项目 | G7: 分模块成绩 | K7: 成绩统计
G8: 模块1 | H8: 模块2 | I8: 模块3
B9: A | C9: 1 | D9: 模块1-主要尺寸 | F9: 配分 | G9: 18
F10: 实际得分 | G10: =SUM(#REF!) -> #REF! | K10: =SUM(G10:J10) -> #REF!
B11: A | C11: 2 | D11: 模块2-主要尺寸 | F11: 配分 | H11: 18
F12: 实际得分 | H12: =SUM('MOD2-评分表'!L35) -> 0 | K12: =SUM(G12:J12) -> 0
B13: A | C13: 3 | D13: 模块3-主要尺寸 | F13: 配分 | I13: 18
F14: 实际得分 | K14: =SUM(G14:J14) -> 0
B15: B | C15: 1 | D15: 模块1-次要尺寸 | F15: 配分 | G15: 7
F16: 实际得分 | G16: =SUM(#REF!) -> #REF! | K16: =SUM(G16:J16) -> #REF!
B17: B | C17: 2 | D17: 模块2-次要尺寸 | F17: 配分 | H17: 7
F18: 实际得分 | H18: =SUM('MOD2-评分表'!L61) -> 0 | K18: =SUM(G18:J18) -> 0
B19: B | C19: 3 | D19: 模块3-次要尺寸 | F19: 配分 | I19: 7
F20: 实际得分 | K20: =SUM(G20:J20) -> 0
B21: C | C21: 1 | D21: 模块1-表面质量 | F21: 配分 | G21: 3
F22: 实际得分 | G22: =SUM(#REF!) -> #REF! | K22: =SUM(G22:J22) -> #REF!
B23: C | C23: 2 | D23: 模块2-表面质量 | F23: 配分 | H23: 3
F24: 实际得分 | H24: =SUM('MOD2-评分表'!L72) -> 0 | K24: =SUM(G24:J24) -> 0
B25: C | C25: 3 | D25: 模块3-表面质量 | F25: 配分 | I25: 3
F26: 实际得分 | K26: =SUM(G26:J26) -> 0
B27: D | C27: 1 | D27: 模块1-主观评判 | F27: 配分 | G27: 3.3
F28: 实际得分 | G28: =SUM(#REF!) -> #REF! | K28: =SUM(G28:J28) -> #REF!
B29: D | C29: 2 | D29: 模块2-主观评判 | F29: 配分 | H29: 3.3
F30: 实际得分 | H30: =SUM('MOD2-评分表'!L88) -> 0 | K30: =SUM(G30:J30) -> 0
B31: D | C31: 3 | D31: 模块3-主观评判 | F31: 配分 | I31: 3.4
F32: 实际得分 | K32: =SUM(G32:J32) -> 0
B33: E | C33: 1 | D33: 模块1-是否增加毛坯 | F33: 配分 | G33: 2
F34: 实际得分 | G34: =SUM(#REF!) -> #REF! | K34: =SUM(G34:J34) -> #REF!
B35: E | C35: 2 | D35: 模块2-是否增加毛坯 | F35: 配分 | H35: 2
F36: 实际得分 | H36: =SUM('MOD2-评分表'!L92) -> 3 | K36: =SUM(G36:J36) -> 3
B37: E | C37: 3 | D37: 模块3-是否增加毛坯 | F37: 配分 | I37: 2
F38: 实际得分 | K38: =SUM(G38:J38) -> 0
F40: 配分 | G40: =SUM(G9+G15+G21+G27+G33) -> 33.3 | H40: =SUM(H11+H17+H23+H29+H35) -> 33.3 | I40: =SUM(I13+I19+I25+I31+I37) -> 33.4 | J40: 配分 | K40: =SUM(G40:J40) -> 100
F41: 实际得分 | G41: =SUM(G10+G16+G22+G28+G34) -> #REF! | H41: =SUM(H12+H18+H24+H30+H36) -> 3 | I41: 0 | J41: 总成绩 | K41: =SUM(G41:J41) -> #REF!
G43: 选手指导签名
G45: 裁判长签名

Sheet MOD2-评分表
B1: 2014年中国技能大赛—第43届世界技能大赛数控铣项目全国选拔赛MOD2样题评分表
B3: 单位（学校） | E3: =T(成绩单!E4) | G3: 选手编号 | I3: =T(成绩单!I4)
B4: 选手姓名 | E4: =T(成绩单!E5) | G4: 试题图号 | I4: MOD2 | K4: 成绩小计 | L4: =SUM(L7:L91) -> 3
B6: 序号 | C6: 配分 | D6: 方位 | E6: 尺寸类型 | F6: 公称尺寸 | G6: 上偏差 | H6: 下偏差 | I6: 上极限尺寸 | J6: 下极限尺寸 | K6: 实际尺寸 | L6: 得分 | M6: 修正值
B7: A-主要尺寸
B8: 1 | C8: 1 | D8: A4 | E8: 直径 | F8: 2X10 | G8: 0.015 | H8: 0 | I8: 10.015 | J8: 10
B9: 2 | C9: 1 | D9: B4 | E9: 长度 | F9: 22 | G9: 0 | H9: -0.021 | I9: =SUM(G9) -> 0 | J9: =SUM(H9) -> -0.021
B10: 3 | C10: 1 | D10: C4 | E10: 长度 | F10: 14 | G10: 0 | H10: -0.018 | I10: =SUM(F10+G10) -> 14 | J10: =SUM(F10+H10) -> 13.982
B11: 4 | C11: 1 | D11: D4 | E11: 螺纹 | F11: 2XM10
B12: 5 | C12: 1 | D12: B2 | E12: 螺纹 | F12: M42X1.5
B13: 6 | C13: 1 | D13: B3 | E13: 长度 | F13: 16 | G13: 0 | H13: 0.027 | I13: =SUM(F13+G13) -> 16 | J13: =SUM(F13+H13) -> 16.027
B14: 7 | C14: 1 | D14: A5 | E14: 长度 | F14: 12 | G14: -0.006 | H14: -0.024 | I14: =SUM(F14+G14) -> 11.994 | J14: =SUM(F14+H14) -> 11.976
B15: 8 | C15: 1 | D15: B5 | E15: 长度 | F15: 17 | G15: 0.034 | H15: 0.016 | I15: =SUM(F15+G15) -> 17.034 | J15: =SUM(F15+H15) -> 17.016
B16: 9 | C16: 1 | D16: C5 | E16: 长度 | F16: 9 | G16: -0.013 | H16: -0.035 | I16: =SUM(F16+G16) -> 8.987 | J16: =SUM(F16+H16) -> 8.965
B17: 10 | C17: 1 | D17: D5 | E17: 长度 | F17: 47 | G17: -0.009 | H17: -0.034 | I17: =SUM(F17+G17) -> 46.991 | J17: =SUM(F17+H17) -> 46.966
B18: 11 | C18: 1 | D18: B6 | E18: 长度 | F18: 5 | G18: 0.012 | H18: 0 | I18: =SUM(F18+G18) -> 5.012 | J18: =SUM(F18+H18) -> 5
B19: 12 | C19: 1 | D19: A6 | E19: 平行度 | G19: 0.02 | H19: 0 | I19: =SUM(F19+G19) -> 0.02 | J19: =SUM(F19+H19) -> 0
B20: 13 | C20: 1 | D20: A8 | E20: 长度 | F20: 96 | G20: -0.036 | H20: -0.058 | I20: =SUM(F20+G20) -> 95.964 | J20: =SUM(F20+H20) -> 95.942
B21: 14 | C21: 1 | D21: A8 | E21: 长度 | F21: 48 | G21: 0.05 | H21: 0.025 | I21: =SUM(F21+G21) -> 48.05 | J21: =SUM(F21+H21) -> 48.025
B22: 15 | C22: 1 | D22: B9 | E22: 长度 | F22: 26 | G22: 0.041 | H22: 0.02 | I22: =SUM(F22+G22) -> 26.041 | J22: =SUM(F22+H22) -> 26.02
B23: 16 | C23: 1 | D23: B9 | E23: 长度 | F23: 94 | G23: -0.012 | H23: -0.034 | I23: =SUM(F23+G23) -> 93.988 | J23: =SUM(F23+H23) -> 93.966
B24: 17 | C24: 1 | D24: D9 | E24: 长度 | F24: 100 | G24: -0.036 | H24: -0.058 | I24: =SUM(F24+G24) -> 99.964 | J24: =SUM(F24+H24) -> 99.942
B25: 18 | C25: 1 | D25: D7 | E25: 长度 | F25: 94 | G25: 0.035 | H25: 0 | I25: =SUM(F25+G25) -> 94.035 | J25: =SUM(F25+H25) -> 94
B26: 19 | C26: 1 | D26: D7 | E26: 长度 | F26: 48 | G26: 0.025 | H26: 0 | I26: =SUM(F26+G26) -> 48.025 | J26: =SUM(F26+H26) -> 48
B27: 20 | C27: 1 | D27: D7 | E27: 长度 | F27: 24 | G27: 0 | H27: -0.021 | I27: =SUM(F27+G27) -> 24 | J27: =SUM(F27+H27) -> 23.979
B28: 21 | C28: 1 | D28: C6 | E28: 长度 | F28: 100 | G28: 0.034 | H28: 0.012 | I28: =SUM(F28+G28) -> 100.034 | J28: =SUM(F28+H28) -> 100.012
B29: 22 | C29: 1 | D29: B6 | E29: 长度 | F29: 50 | G29: 0.05 | H29: 0.025 | I29: =SUM(G29) -> 0.05 | J29: =SUM(H29) -> 0.025
B30: 23 | C30: 1 | D30: B7 | E30: 长度 | F30: 22 | G30: 0.041 | H30: 0.02 | I30: =SUM(F30+G30) -> 22.041 | J30: =SUM(F30+H30) -> 22.02
B31: 24 | C31: 1 | D31: B8 | E31: 长度 | F31: 24 | G31: -0.02 | H31: -0.041 | I31: =SUM(F31+G31) -> 23.98 | J31: =SUM(F31+H31) -> 23.959
B32: 25 | C32: 1 | D32: C8 | E32: 长度 | F32: 22 | G32: -0.02 | H32: -0.041 | I32: =SUM(F32+G32) -> 21.98 | J32: =SUM(F32+H32) -> 21.959
B33: 26 | C33: 1 | D33: C7 | E33: 长度 | F33: 24 | G33: 0.021 | H33: 0 | I33: =SUM(F33+G33) -> 24.021 | J33: =SUM(F33+H33) -> 24
B34: 27 | C34: 1 | D34: C7 | E34: 长度 | F34: 10 | G34: -0.013 | H34: -0.028 | I34: =SUM(F34+G34) -> 9.987 | J34: =SUM(F34+H34) -> 9.972
B35: 小计 | C35: =SUM(C8:C34) -> 27
B37: B-次要尺寸
B38: 1 | C38: 0.5 | D38: B1 | E38: 长度 | F38: 89 | G38: 0.1 | H38: -0.1 | I38: 89.1 | J38: 88.9 | L38: =IF(K38=I38,(IF(K38<>J38,C38,0)),0) -> 0
B39: 2 | C39: 0.5 | D39: B2 | E39: 长度 | F39: 73 | G39: 0.1 | H39: -0.1 | I39: 73.1 | J39: 72.9 | L39: =IF(K39=I39,(IF(K39<>J39,C39,0)),0) -> 0
B40: 3 | C40: 0.5 | D40: B2 | E40: 长度 | F40: 37 | G40: 0.1 | H40: -0.1 | I40: 37.1 | J40: 36.9 | L40: =IF(K40=I40,(IF(K40<>J40,C40,0)),0) -> 0
B41: 4 | C41: 0.5 | D41: A3 | E41: 长度 | F41: 49 | G41: 0.1 | H41: -0.1 | I41: 49.1 | J41: 39.9 | L41: =IF(K41=I41,(IF(K41<>J41,C41,0)),0) -> 0
B42: 5 | C42: 0.5 | D42: A4 | E42: 直径 | F42: 70 | G42: 0.1 | H42: -0.1 | I42: 70.1 | J42: =SUM(F42+H42) -> 69.9 | L42: =IF(K42>=(J42-M42),(IF(K42<=(I42+M42),C42,0)),0) -> 0
B43: 6 | C43: 0.5 | D43: B4 | E43: 长度 | F43: 41 | G43: 0.1 | H43: -0.1 | I43: =SUM(F43+G43) -> 41.1 | J43: =SUM(F43+H43) -> 40.9 | L43: =IF(K43>=(J43-M43),(IF(K43<=(I43+M43),C43,0)),0) -> 0
...
