Workbook

Sheet Total
AU2: Page 1 of 1
P3: Objective Marking Form
AU4: 24-08-2012
P6: China Team Training 2012 | AU6: 0.96415509
B10: Skill No. | J10: 0 | L10: 7 | P10: Skill | U10: CNC Milling
B13: Competitor No. | P13: Competitor Name | AS13: Member
B16: Criterion ID | J16: Criterion Description | AH16: Marks Awarded | AU16: Total Award
AH18: Day 1 | AL18: Day 2 | AP18: Day 3
B20: A | J20: Main dimensions | AE20: Max | AH20: 18 | AL20: 18 | AP20: 18
AE21: Actual
B22: B | J22: Secondary dimensions | AE22: Max | AH22: 7 | AL22: 7 | AP22: 7
AE23: Actual
B24: C | J24: Surface quality | AE24: Max | AH24: 3 | AL24: 3 | AP24: 3
AE25: Actual
B26: D | J26: Conformity with drawing | AE26: Max | AH26: 3.3 | AL26: 3.3 | AP26: 3.4
AE27: Actual
B28: E | J28: No additional material used | AE28: Max | AH28: 2 | AL28: 2 | AP28: 2
AE29: Actual
AE30: Max
AE31: Actual
AE32: Max
AE33: Actual
AE34: Max
AE35: Actual
AE37: Max | AH37: =SUM(AH20+AH22+AH24+AH26+AH28) -> 33.3 | AL37: =SUM(AL20+AL22+AL24+AL26+AL28) -> 33.3 | AP37: =SUM(AP20+AP22+AP24+AP26+AP28) -> 33.4 | AU37: =SUM(AH37:AS38) -> 100
Z38: Total
AE39: Actual | AH39: =SUM(AH21+AH23+AH25+AH27+AH29) -> 0 | AL39: =SUM(AL21+AL23+AL25+AL27+AL29) -> 0 | AP39: =SUM(AP21+AP23+AP25+AP27+AP29) -> 0
B42: Sub Criterion ID | J42: Sub Criterion Description | AH42: Marks Awarded | AU42: Total Award
AH44: Day 1 | AL44: Day 2 | AP44: Day 3
B46: A | F46: 1 | J46: Main Dimension for Project 1 | AE46: Max | AH46: 18
AE47: Actual
B48: A | F48: 2 | J48: Main Dimension for Project 2 | AE48: Max | AL48: 18
AE49: Actual | AL49: =SUM('A-Main Dimension'!AX54:BB55) -> 0
B50: A | F50: 3 | J50: Main Dimension for Project 3 | AE50: Max | AP50: 18
AE51: Actual
B52: B | F52: 1 | J52: Secundary Dimension for Project 1 | AE52: Max | AH52: 7
AE53: Actual
B54: B | F54: 2 | J54: Secundary Dimension for Project 2 | AE54: Max | AL54: 7
AE55: Actual | AL55: =SUM('B-Secundary Dimension'!AX54:BB55) -> 0
B56: B | F56: 3 | J56: Secundary Dimension for Project 3 | AE56: Max | AP56: 7
...

Sheet A-Main Dimension
M3: Objective Marking Form
M6: China Team Training 2012
AN10: Sub Criterion ID | AY10: A
B13: Skill No. | J13: 0 | L13: 7 | P13: Skill | U13: CNC Milling | AN13: Competition Day | AY13: 2
B16: Competitor No. | P16: Competitor Name | AS16: Member
B19: Sub Criterion | M19: Main Dimension for M2-1
B22: Aspect ID | F22: Max Mark | I22: Aspect of Criterion - Description | AG22: Requirement or Nominal Size | AO22: Result or Actual Value | AX22: Mark Awarded | BD22: 1/0
B24: 1 | F24: 0.6 | I24: D7 | AG24: 42+0/-0.02
B25: 2 | F25: 0.6 | I25: D2 | AG25: 20+0.025/0
B26: 3 | F26: 0.5 | I26: C4 | AG26: 10+0.02/0
B27: 4 | F27: 0.5 | I27: C5 | AG27: 10+0.02/0
B28: 5 | F28: 0.6 | I28: B4 | AG28: 74+0/-0.025
B29: 6 | F29: 0.6 | I29: E4 | AG29: 74+0/-0.025
B30: 7 | F30: 0.6 | I30: C4 | AG30: 12+0.023/0
B31: 8 | F31: 0.7 | I31: C9 | AG31: 3.5+0.025/0
B32: 9 | F32: 0.7 | I32: C9 | AG32: 25+0.025/0
B33: 10 | F33: 0.5 | I33: E4 | AG33: 12+0/-0.023
B34: 11 | F34: 0.5 | I34: E4 | AG34: 12+0.018/0
B35: 12 | F35: 0.5 | I35: E5 | AG35: 12+0.018/0
... B51: 28 | F51: 0.8 | I51: B3 | AG51: //0.02
F54: =SUM(F24:H51) -> 18 | I54: Maximum Mark for Sub Criterion | AN54: Mark Awarded | AX54: =SUM(AX24:BB51) -> 0
B58: Signatures confirming the accuracy of this printed result
B60: Compatriot or Independent Expert | S60: Chief Expert
AK61: Mark Awarded is the Max Mark minus any
AK62: specified deductions for difference between
AK63: Requirement and Result
S64: Date and Time
B67: Page 1/1 | AP67: 41113

Sheet B-Secundary Dimension
M3: Objective Marking Form
M6: China Team Training 2012
AN10: Sub Criterion ID | AY10: B
B13: Skill No. | J13: 0 | L13: 7 | P13: Skill | U13: CNC Milling | AN13: Competition Day | AY13: 2
B16: Competitor No. | P16: Competitor Name | AS16: Member
B19: Sub Criterion | M19: Secundary Dimension for M2-1
B22: Aspect ID | F22: Max Mark | I22: Aspect of Criterion - Description | AG22: Requirement or Nominal Size | AO22: Result or Actual Value | AX22: Mark Awarded | BD22: 1/0
B24: 1 | F24: 0.3 | I24: C2 | AG24: 10+0.1/-0.1
B25: 2 | F25: 0.3 | I25: E2 | AG25: 8+0.1/-0.1
B26: 3 | F26: 0.3 | I26: D4 | AG26: 50+0.1/-0.1
B27: 4 | F27: 0.3 | I27: C4 | AG27: 20+0.1/-0.1
B28: 5 | F28: 0.3 | I28: C5 | AG28: 20+0.1/-0.1
B29: 6 | F29: 0.3 | I29: B5 | AG29: 6+0.1/-0.1
B30: 7 | F30: 0.3 | I30: C6 | AG30: 9+0.1/-0.1
B31: 8 | F31: 0.3 | I31: B7 | AG31: 25+0.1/-0.1
B32: 9 | F32: 0.7 | I32: D2 | AG32: M35X1.5/12+2
B33: 10 | F33: 0.4 | I33: C8 | AG33: M10/12+2
B34: 11 | F34: 0.4 | I34: C9 | AG34: M10/12+2
B35: 12 | F35: 0.4 | I35: E8 | AG35: M10/12+2
... B39: 16 | F39: 0.3 | I39: D8 | AG39: 11+0.1/-0.1
B40: 17 | F40: 0.3 | I40: D8 | AG40: 32
B41: 18 | F41: 0.3 | I41: C3 | AG41: 48+/-0.02
B42: 19 | F42: 0.3 | I42: D8 | AG42: 8+/-0.1
B43: 20 | F43: 0.3 | I43: D4 | AG43: 39+/-0.2
B44: 21
B45: 22
B46: 23
B47: 24
B48: 25
B49: 26
B50: 27
B51: 28
F54: =SUM(F24:H51) -> 7 | I54: Maximum Mark for Sub Criterion | AN54: Mark Awarded | AX54: =SUM(AX24:BB51) -> 0
B58: Signatures confirming the accuracy of this printed result
B60: Compatriot or Independent Expert | S60: Chief Expert
AK61: Mark Awarded is the Max Mark minus any
AK62: specified deductions for difference between
AK63: Requirement and Result
S64: Date and Time
B67: Page 1/1

Sheet C-Surface Quality
M3: Objective Marking Form
M6: China Team Training 2012
AN10: Sub Criterion ID | AY10: C
B13: Skill No. | J13: 0 | L13: 7 | P13: Skill | U13: CNC Milling | AN13: Competition Day | AY13: 2
B16: Competitor No. | P16: Competitor Name | AS16: Member
B19: Sub Criterion | M19: Surface Quality for M2-1
B22: Aspect ID | F22: Max Mark | I22: Aspect of Criterion - Description | AG22: Requirement or Nominal Size | AO22: Result or Actual Value | AX22: Mark Awarded | BD22: 1/0
B24: 1 | F24: 0.4 | I24: E4 | AG24: Ra 0.8 | AX24: =SUM(F24*BD24) -> 0 | BD24: 0
B25: 2 | F25: 0.4 | I25: E5 | AG25: Ra 0.8 | AX25: =SUM(F25*BD25) -> 0 | BD25: 0
B26: 3 | F26: 0.4 | I26: D8 | AG26: Ra 0.8 | AX26: =SUM(F26*BD26) -> 0 | BD26: 0
B27: 4 | F27: 0.4 | I27: D9 | AG27: Ra 0.8 | AX27: =SUM(F27*BD27) -> 0 | BD27: 0
B28: 5 | F28: 0.5 | I28: D7 | AG28: Ra 0.8 | AX28: =SUM(F28*BD28) -> 0 | BD28: 0
B29: 6 | F29: 0.5 | I29: E4 | AG29: Ra 0.8 | AX29: =SUM(F29*BD29) -> 0 | BD29: 0
B30: 7 | F30: 0.4 | I30: F4 | AG30: Ra 0.8 | AX30: =SUM(F30*BD30) -> 0 | BD30: 0
B31: 8 | AX31: =SUM(F31*BD31) -> 0 | BD31: 0
B32: 9
B33: 10
B34: 11
B35: 12
B36: 13
B37: 14
B38: 15
B39: 16
B40: 17
B41: 18
B42: 19
B43: 20
... B51: 28
F54: =SUM(F24:H51) -> 3 | I54: Maximum Mark for Sub Criterion | AN54: Mark Awarded | AX54: =SUM(AX24:BB51) -> 0
B58: Signatures confirming the accuracy of this printed result
B60: Compatriot or Independent Expert | S60: Chief Expert
AK61: Mark Awarded is the Max Mark minus any
AK62: specified deductions for difference between
AK63: Requirement and Result
S64: Date and Time
B67: Page 1/1

Sheet E-additional material 
M3: Objective Marking Form
M6: China Team Training 2012
AN10: Sub Criterion ID | AY10: E
B13: Skill No. | J13: 0 | L13: 7 | P13: Skill | U13: CNC Milling | AN13: Competition Day | AY13: 2
B16: Competitor No. | P16: Competitor Name | AS16: Member
B19: Sub Criterion | M19: No additional material used for M2-1
B22: Aspect ID | F22: Max Mark | I22: Aspect of Criterion - Description | AG22: Requirement or Nominal Size | AO22: Result or Actual Value | AX22: Mark Awarded | BD22: 1/0
B24: 1 | F24: 2 | I24: No additional material used for Project 1 | AO24: 0 | AX24: =IF(AO24=0,F24,(AO24-1)*(-F24)) -> 2 | BD24: 0
B25: 2
B26: 3
B27: 4
B28: 5
B29: 6
B30: 7
B31: 8
B32: 9
B33: 10
B34: 11
B35: 12
B36: 13
... B51: 28
F54: =SUM(F24:H51) -> 2 | I54: Maximum Mark for Sub Criterion | AN54: Mark Awarded | AX54: =SUM(AX24) -> 2
B58: Signatures confirming the accuracy of this printed result
B60: Compatriot or Independent Expert | S60: Chief Expert
AK61: Mark Awarded is the Max Mark minus any
AK62: specified deductions for difference between
AK63: Requirement and Result
S64: Date and Time
B67: Page 1/1

Sheet D-conformity
M3: Subjective Marking Form
M6: China Team Training 2012
AM10: Sub Criterion ID | AX10: D
B13: Skill No. | J13: 0 | L13: 7 | P13: Skill | U13: CNC Milling | AM13: Competition Day | AX13: 2
B16: Competitor No. | P16: Competitor Name
B19: Sub Criterion | M19: In conformity with drawing M2-1
B22: Aspect ID | F22: Max Mark | I22: Aspect of Criterion - Description | AG22: Experts Score (1 to 10) | AW22: Mark Awarded
AG24: 1 | AJ24: 2 | AM24: 3 | AP24: 4 | AS24: 5
B25: 1 | F25: 0.8 | I25: Chamfering edges by machine | AW25: =SUM(F25*(BL25-BK25-BJ25)/30) -> 0 | BD25: =SUM(10-AG25) -> 10 | BE25: =SUM(10-AJ25) -> 10 | BF25: =SUM(10-AM25) -> 10 | BG25: =SUM(10-AP25) -> 10 | BH25: =SUM(10-AS25) -> 10 | BI25: =MAX(BD25:BH25) -> 10 | BJ25: =SUM(10-BI25) -> 0 | BK25: =MAX(AG25:AU25) -> 0 | BL25: =SUM(AG25:AU25) -> 0
B26: 2 | F26: 0.5 | I26: Edge Chamfering by Hand 0,2-0,3x45º | AW26: =SUM(F26*(BL26-BK26-BJ26)/30) -> 0 | BD26: =SUM(10-AG26) -> 10 | BE26: =SUM(10-AJ26) -> 10 | BF26: =SUM(10-AM26) -> 10 | BG26: =SUM(10-AP26) -> 10 | BH26: =SUM(10-AS26) -> 10 | BI26: =MAX(BD26:BH26) -> 10 | BJ26: =SUM(10-BI26) -> 0 | BK26: =MAX(AG26:AU26) -> 0 | BL26: =SUM(AG26:AU26) -> 0
B27: 3 | F27: 0.6 | I27: Damage in Contour | AW27: =SUM(F27*(BL27-BK27-BJ27)/30) -> 0 | BD27: =SUM(10-AG27) -> 10 | BE27: =SUM(10-AJ27) -> 10 | BF27: =SUM(10-AM27) -> 10 | BG27: =SUM(10-AP27) -> 10 | BH27: =SUM(10-AS27) -> 10 | BI27: =MAX(BD27:BH27) -> 10 | BJ27: =SUM(10-BI27) -> 0 | BK27: =MAX(AG27:AU27) -> 0 | BL27: =SUM(AG27:AU27) -> 0
B28: 4 | F28: 0.7 | I28: Conformity with drawing - First Surface | AW28: =SUM(F28*(BL28-BK28-BJ28)/30) -> 0 | BD28: =SUM(10-AG28) -> 10 | BE28: =SUM(10-AJ28) -> 10 | BF28: =SUM(10-AM28) -> 10 | BG28: =SUM(10-AP28) -> 10 | BH28: =SUM(10-AS28) -> 10 | BI28: =MAX(BD28:BH28) -> 10 | BJ28: =SUM(10-BI28) -> 0 | BK28: =MAX(AG28:AU28) -> 0 | BL28: =SUM(AG28:AU28) -> 0
B29: 5 | F29: 0.7 | I29: Comformity with drawing - Second surface | AW29: =SUM(F29*(BL29-BK29-BJ29)/30) -> 0 | BD29: =SUM(10-AG29) -> 10 | BE29: =SUM(10-AJ29) -> 10 | BF29: =SUM(10-AM29) -> 10 | BG29: =SUM(10-AP29) -> 10 | BH29: =SUM(10-AS29) -> 10 | BI29: =MAX(BD29:BH29) -> 10 | BJ29: =SUM(10-BI29) -> 0 | BK29: =MAX(AG29:AU29) -> 0 | BL29: =SUM(AG29:AU29) -> 0
B30: 6 | AW30: =SUM(F30*(BL30-BK30-BJ30)/30) -> 0 | BD30: =SUM(10-AG30) -> 10 | BE30: =SUM(10-AJ30) -> 10 | BF30: =SUM(10-AM30) -> 10 | BG30: =SUM(10-AP30) -> 10 | BH30: =SUM(10-AS30) -> 10 | BI30: =MAX(BD30:BH30) -> 10 | BJ30: =SUM(10-BI30) -> 0 | BK30: =MAX(AG30:AU30) -> 0 | BL30: =SUM(AG30:AU30) -> 0
AW31: =SUM(AG31:AU31)/5 -> 0
AW32: =SUM(AG32:AU32)/5 -> 0
F55: =SUM(F25:H52) -> 3.3 | I55: Maximum Mark for Sub Criterion | AN55: Mark Awarded | AW55: =SUM(AW25:BA30) -> 0
B59: Signatures confirming the accuracy of this printed result
B61: Compatriot or Independent Expert | S61: Chief Expert
S65: Date and Time
B68: Page 1/1
