Workbook

Sheet 成绩单
B2: 2014年中国技能大赛—第43届世界技能大赛数控铣项目全国选拔赛样题评分汇总表
B4: 单位（学校） | G4: 选手编号
B5: 选手姓名
B7: 评判项目编码 | D7: 评判项目 | G7: 分模块成绩 | K7: 成绩统计
G8: 模块1 | H8: 模块2 | I8: 模块3
B9: A | C9: 1 | D9: 模块1-主要尺寸 | F9: 配分 | G9: 18
F10: 实际得分 | G10: =SUM('MOD1-评分表'!L41) -> 1 | K10: =SUM(G10:J10) -> 1
B11: A | C11: 2 | D11: 模块2-主要尺寸 | F11: 配分 | H11: 18
F12: 实际得分 | H12: =SUM('MOD2-评分表'!L39) -> 0 | K12: =SUM(G12:J12) -> 0
B13: A | C13: 3 | D13: 模块3-主要尺寸 | F13: 配分 | I13: 18
F14: 实际得分 | K14: =SUM(G14:J14) -> 0
B15: B | C15: 1 | D15: 模块1-次要尺寸 | F15: 配分 | G15: 7
F16: 实际得分 | G16: =SUM('MOD1-评分表'!L67) -> 0 | K16: =SUM(G16:J16) -> 0
B17: B | C17: 2 | D17: 模块2-次要尺寸 | F17: 配分 | H17: 7
F18: 实际得分 | H18: =SUM('MOD2-评分表'!L64) -> 0 | K18: =SUM(G18:J18) -> 0
B19: B | C19: 3 | D19: 模块3-次要尺寸 | F19: 配分 | I19: 7
F20: 实际得分 | K20: =SUM(G20:J20) -> 0
B21: C | C21: 1 | D21: 模块1-表面质量 | F21: 配分 | G21: 3
F22: 实际得分 | G22: =SUM('MOD1-评分表'!L78) -> 0 | K22: =SUM(G22:J22) -> 0
B23: C | C23: 2 | D23: 模块2-表面质量 | F23: 配分 | H23: 3
F24: 实际得分 | H24: =SUM('MOD2-评分表'!L75) -> 0 | K24: =SUM(G24:J24) -> 0
B25: C | C25: 3 | D25: 模块3-表面质量 | F25: 配分 | I25: 3
F26: 实际得分 | K26: =SUM(G26:J26) -> 0
B27: D | C27: 1 | D27: 模块1-主观评判 | F27: 配分 | G27: 3.3
F28: 实际得分 | G28: =SUM('MOD1-评分表'!L94) -> 0 | K28: =SUM(G28:J28) -> 0
B29: D | C29: 2 | D29: 模块2-主观评判 | F29: 配分 | H29: 3.3
F30: 实际得分 | H30: =SUM('MOD2-评分表'!L91) -> 0 | K30: =SUM(G30:J30) -> 0
B31: D | C31: 3 | D31: 模块3-主观评判 | F31: 配分 | I31: 3.4
F32: 实际得分 | K32: =SUM(G32:J32) -> 0
B33: E | C33: 1 | D33: 模块1-是否增加毛坯 | F33: 配分 | G33: 2
F34: 实际得分 | G34: =SUM('MOD1-评分表'!L98) -> 2 | K34: =SUM(G34:J34) -> 2
B35: E | C35: 2 | D35: 模块2-是否增加毛坯 | F35: 配分 | H35: 2
F36: 实际得分 | H36: =SUM('MOD2-评分表'!L95) -> 2 | K36: =SUM(G36:J36) -> 2
B37: E | C37: 3 | D37: 模块3-是否增加毛坯 | F37: 配分 | I37: 2
F38: 实际得分 | K38: =SUM(G38:J38) -> 0
F40: 配分 | G40: =SUM(G9+G15+G21+G27+G33) -> 33.3 | H40: =SUM(H11+H17+H23+H29+H35) -> 33.3 | I40: =SUM(I13+I19+I25+I31+I37) -> 33.4 | J40: 配分 | K40: =SUM(G40:J40) -> 100
F41: 实际得分 | G41: =SUM(G10+G16+G22+G28+G34) -> 3 | H41: =SUM(H12+H18+H24+H30+H36) -> 2 | I41: 0 | J41: 总成绩 | K41: =SUM(G41:J41) -> 5
G43: 选手指导签名
G45: 裁判长签名

Sheet MOD1-评分表
B1: 2014年中国技能大赛—第43届世界技能大赛数控铣项目全国选拔赛MOD1样题评分表
B3: 单位（学校） | E3: =T(成绩单!E4) | G3: 选手编号 | I3: =T(成绩单!I4)
B4: 选手姓名 | E4: =T(成绩单!E5) | G4: 试题图号 | I4: MOD1 | K4: 成绩小计 | L4: =SUM(L7:L97) -> 4
B6: 序号 | C6: 配分 | D6: 方位 | E6: 尺寸类型 | F6: 公称尺寸 | G6: 上偏差 | H6: 下偏差 | I6: 上极限尺寸 | J6: 下极限尺寸 | K6: 实际尺寸 | L6: 得分 | M6: 偏差
B7: A-主要尺寸 | L7: 允差 | M7: 0.003
B8: 1 | C8: 1.5 | D8: B3 | E8: 长度 | F8: 11 | G8: 0.015 | H8: -0.015 | I8: =SUM(F8+G8) -> 11.015 | J8: =SUM(F8+H8) -> 10.985 | L8: =IF(K8>=(J8-M8-$M$7),(IF(K8<=(I8+M8+$M$7),C8,0)),0) -> 0
B9: 2 | C9: 1 | D9: A5 | E9: 长度 | F9: 10 | G9: 0.02 | H9: 0 | I9: =SUM(F9+G9) -> 10.02 | J9: =SUM(F9+H9) -> 10 | L9: =IF(K9>=(J9-M9-$M$7),(IF(K9<=(I9+M9+$M$7),C9,0)),0) -> 0
B10: 3 | C10: 1.5 | D10: B5 | E10: 长度 | F10: 12 | G10: 0.01 | H10: -0.01 | I10: =SUM(F10+G10) -> 12.01 | J10: =SUM(F10+H10) -> 11.99 | L10: =IF(K10>=(J10-M10-$M$7),(IF(K10<=(I10+M10+$M$7),C10,0)),0) -> 0
B11: 4 | C11: 1 | D11: C1 | E11: 长度 | F11: 10 | G11: 0.02 | H11: 0 | I11: =SUM(F11+G11) -> 10.02 | J11: =SUM(F11+H11) -> 10 | L11: =IF(K11>=(J11-M11-$M$7),(IF(K11<=(I11+M11+$M$7),C11,0)),0) -> 0
B12: 5 | C12: 1 | D12: D4 | E12: 长度 | F12: 92 | G12: 0.04 | H12: 0 | I12: =SUM(F12+G12) -> 92.04 | J12: =SUM(F12+H12) -> 92 | L12: =IF(K12>=(J12-M12-$M$7),(IF(K12<=(I12+M12+$M$7),C12,0)),0) -> 0
B13: 6 | C13: 1 | D13: D4 | E13: 长度 | F13: 80 | G13: 0.03 | H13: 0 | I13: =SUM(F13+G13) -> 80.03 | J13: =SUM(F13+H13) -> 80 | L13: =IF(K13>=(J13-M13-$M$7),(IF(K13<=(I13+M13+$M$7),C13,0)),0) -> 0
B14: 7 | C14: 1 | D14: D3 | E14: 长度 | F14: 20 | G14: 0.01 | H14: -0.01 | I14: =SUM(F14+G14) -> 20.01 | J14: =SUM(F14+H14) -> 19.99 | L14: =IF(K14>=(J14-M14-$M$7),(IF(K14<=(I14+M14+$M$7),C14,0)),0) -> 0
B15: 8 | C15: 1.5 | D15: D4 | E15: 长度 | F15: 7 | G15: 0.02 | H15: 0 | I15: =SUM(F15+G15) -> 7.02 | J15: =SUM(F15+H15) -> 7 | L15: =IF(K15>=(J15-M15-$M$7),(IF(K15<=(I15+M15+$M$7),C15,0)),0) -> 0
B16: 9 | C16: 1 | D16: C5 | E16: 长度 | F16: 80 | G16: 0 | H16: -0.03 | I16: =SUM(F16+G16) -> 80 | J16: =SUM(F16+H16) -> 79.97 | L16: =IF(K16>=(J16-M16-$M$7),(IF(K16<=(I16+M16+$M$7),C16,0)),0) -> 0
B17: 10 | C17: 1 | D17: C5 | E17: 长度 | F17: 92 | G17: 0.02 | H17: -0.02 | I17: =SUM(F17+G17) -> 92.02 | J17: =SUM(F17+H17) -> 91.98 | L17: =IF(K17>=(J17-M17-$M$7),(IF(K17<=(I17+M17+$M$7),C17,0)),0) -> 0
B18: 11 | C18: 1.5 | D18: C6 | E18: 直径 | F18: 20 | G18: 0.02 | H18: 0 | I18: =SUM(F18+G18) -> 20.02 | J18: =SUM(F18+H18) -> 20 | L18: =IF(K18>=(J18-M18-$M$7),(IF(K18<=(I18+M18+$M$7),C18,0)),0) -> 0
B19: 12 | C19: 1 | D19: B6 | E19: 直径 | F19: 10 | G19: 0.018 | H19: 0 | I19: =SUM(F19+G19) -> 10.018 | J19: =SUM(F19+H19) -> 10 | L19: =IF(K19>=(J19-M19-$M$7),(IF(K19<=(I19+M19+$M$7),C19,0)),0) -> 0
... B23: 16 | C23: 1.5 | D23: D9 | E23: 长度 | F23: 12 | G23: 0 | H23: -0.02 | I23: =SUM(F23+G23) -> 12 | J23: =SUM(F23+H23) -> 11.98 | L23: =IF(K23>=(J23-M23-$M$7),(IF(K23<=(I23+M23+$M$7),C23,0)),0) -> 0
B24: 17 | C24: 1 | D24: C10 | E24: 长度 | F24: 5 | G24: 0.02 | H24: 0 | I24: =SUM(G24) -> 0.02 | J24: =SUM(H24) -> 0 | L24: =IF(K24>=(J24-M24),(IF(K24<=(I24+M24),C24,0)),0) -> 1
B25: 18 | C25: 1 | D25: C8 | E25: 长度 | F25: 16 | G25: 0.02 | H25: 0 | I25: =SUM(F25+G25) -> 16.02 | J25: =SUM(F25+H25) -> 16 | L25: =IF(K25>=(J25-M25-$M$7),(IF(K25<=(I25+M25+$M$7),C25,0)),0) -> 0
B26: 19 | C26: 1.5 | D26: C9 | E26: 长度 | F26: 9 | G26: 0.02 | H26: 0 | I26: =SUM(F26+G26) -> 9.02 | J26: =SUM(F26+H26) -> 9 | L26: =IF(K26>=(J26-M26-$M$7),(IF(K26<=(I26+M26+$M$7),C26,0)),0) -> 0
B27: 20 | C27: 1 | D27: D9 | E27: 长度 | F27: 98 | G27: 0.03 | H27: 0.06 | I27: =SUM(F27+G27) -> 98.03 | J27: =SUM(F27+H27) -> 98.06 | L27: =IF(K27>=(J27-M27-$M$7),(IF(K27<=(I27+M27+$M$7),C27,0)),0) -> 0
B28: 21 | C28: 1.5 | D28: C7 | E28: 直径 | F28: 42 | G28: 0.03 | H28: 0 | I28: =SUM(F28+G28) -> 42.03 | J28: =SUM(F28+H28) -> 42 | L28: =IF(K28>=(J28-M28-$M$7),(IF(K28<=(I28+M28+$M$7),C28,0)),0) -> 0
B29: 22 | C29: 1 | D29: C10 | E29: 长度 | F29: 98 | G29: -0.05 | H29: -0.08 | I29: =SUM(F29+G29) -> 97.95 | J29: =SUM(F29+H29) -> 97.92 | L29: =IF(K29>=(J29-M29-$M$7),(IF(K29<=(I29+M29+$M$7),C29,0)),0) -> 0
B30: 23 | C30: 1 | D30: B9 | E30: 长度 | F30: 88 | G30: 0.04 | H30: 0.01 | I30: =SUM(F30+G30) -> 88.04 | J30: =SUM(F30+H30) -> 88.01 | L30: =IF(K30>=(J30-M30-$M$7),(IF(K30<=(I30+M30+$M$7),C30,0)),0) -> 0
B31: 24 | I31: =SUM(F31+G31) -> 0 | J31: =SUM(F31+H31) -> 0 | L31: =IF(K31>=(J31-M31),(IF(K31<=(I31+M31),C31,0)),0) -> 0
B32: 25 | I32: =SUM(F32+G32) -> 0 | J32: =SUM(F32+H32) -> 0 | L32: =IF(K32>=(J32-M32),(IF(K32<=(I32+M32),C32,0)),0) -> 0
B33: 26 | I33: =SUM(F33+G33) -> 0 | J33: =SUM(F33+H33) -> 0 | L33: =IF(K33>=(J33-M33),(IF(K33<=(I33+M33),C33,0)),0) -> 0
B34: 27 | I34: =SUM(F34+G34) -> 0 | J34: =SUM(F34+H34) -> 0 | L34: =IF(K34>=(J34-M34),(IF(K34<=(I34+M34),C34,0)),0) -> 0
B35: 28 | I35: =SUM(F35+G35) -> 0 | J35: =SUM(F35+H35) -> 0 | L35: =IF(K35>=(J35-M35),(IF(K35<=(I35+M35),C35,0)),0) -> 0
B36: 29 | I36: =SUM(F36+G36) -> 0 | J36: =SUM(F36+H36) -> 0 | L36: =IF(K36>=(J36-M36),(IF(K36<=(I36+M36),C36,0)),0) -> 0
B37: 30 | I37: =SUM(F37+G37) -> 0 | J37: =SUM(F37+H37) -> 0 | L37: =IF(K37>=(J37-M37),(IF(K37<=(I37+M37),C37,0)),0) -> 0
B38: 31 | I38: =SUM(F38+G38) -> 0 | J38: =SUM(F38+H38) -> 0 | L38: =IF(K38>=(J38-M38),(IF(K38<=(I38+M38),C38,0)),0) -> 0
B39: 32 | I39: =SUM(F39+G39) -> 0 | J39: =SUM(F39+H39) -> 0 | L39: =IF(K39>=(J39-M39),(IF(K39<=(I39+M39),C39,0)),0) -> 0
B40: 33 | I40: =SUM(F40+G40) -> 0 | J40: =SUM(F40+H40) -> 0 | L40: =IF(K40>=(J40-M40),(IF(K40<=(I40+M40),C40,0)),0) -> 0
B41: 小计 | C41: =SUM(C8:C40) -> 27 | L41: =SUM(L8:L40) -> 1
B43: B-次要尺寸
B44: 1 | C44: 1.2 | D44: C7 | E44: 螺纹 | F44: M30X1.5/12+2 | I44: OK | J44: NO | L44: =IF(K44=I44,(IF(K44<>J44,C44,0)),0) -> 0
B45: 2 | C45: 0.8 | D45: D5 | E45: 螺纹 | F45: M10/10+2 | I45: OK | J45: NO | L45: =IF(K45=I45,(IF(K45<>J45,C45,0)),0) -> 0
B46: 3 | C46: 0.5 | D46: B2 | E46: 长度 | F46: 5 | G46: 0.1 | H46: -0.1 | I46: =SUM(F46+G46) -> 5.1 | J46: =SUM(F46+H46) -> 4.9 | L46: =IF(K46>=(J46-M46),(IF(K46<=(I46+M46),C46,0)),0) -> 0
...

Sheet MOD2-评分表
B1: 2014年中国技能大赛—第43届世界技能大赛数控铣项目全国选拔赛MOD2样题评分表
B3: 单位（学校） | E3: =T(成绩单!E4) | G3: 选手编号 | I3: =T(成绩单!I4)
B4: 选手姓名 | E4: =T(成绩单!E5) | G4: 试题图号 | I4: MOD2 | K4: 成绩小计 | L4: =SUM(L7:L94) -> 2
B6: 序号 | C6: 配分 | D6: 方位 | E6: 尺寸类型 | F6: 公称尺寸 | G6: 上偏差 | H6: 下偏差 | I6: 上极限尺寸 | J6: 下极限尺寸 | K6: 实际尺寸 | L6: 得分 | M6: 修正值
B7: A-主要尺寸
B8: 1 | C8: 1 | D8: B1 | E8: 长度 | F8: 10 | G8: 0.02 | H8: 0 | I8: =SUM(F8+G8) -> 10.02 | J8: =SUM(F8+H8) -> 10 | L8: =IF(K8>=(J8-M8),(IF(K8<=(I8+M8),C8,0)),0) -> 0
B9: 2 | C9: 1 | D9: B3 | E9: 长度 | F9: 5 | G9: 0.02 | H9: 0 | I9: =SUM(G9) -> 0.02 | J9: =SUM(H9) -> 0 | L9: =IF(K9>=(J9-M9),(IF(K9<K16=(I9+M9),C9,0)),0) -> 0
B10: 3 | C10: 1 | D10: D1 | E10: 直径 | F10: 30 | G10: 0.025 | H10: 0 | I10: =SUM(F10+G10) -> 30.025 | J10: =SUM(F10+H10) -> 30 | L10: =IF(K10>=(J10-M10),(IF(K10<=(I10+M10),C10,0)),0) -> 0
B11: 4 | C11: 1 | D11: B4 | E11: 长度 | F11: 58 | G11: -0.05 | H11: -0.07 | I11: =SUM(F11+G11) -> 57.95 | J11: =SUM(F11+H11) -> 57.93 | L11: =IF(K11>=(J11-M11),(IF(K11<=(I11+M11),C11,0)),0) -> 0
B12: 5 | C12: 1 | D12: B4 | E12: 长度 | F12: 47 | G12: 0 | H12: -0.02 | I12: =SUM(F12+G12) -> 47 | J12: =SUM(F12+H12) -> 46.98 | L12: =IF(K12>=(J12-M12),(IF(K12<=(I12+M12),C12,0)),0) -> 0
B13: 6 | C13: 1 | D13: B3 | E13: 长度 | F13: 2 | G13: 0.02 | H13: 0 | I13: =SUM(F13+G13) -> 2.02 | J13: =SUM(F13+H13) -> 2 | L13: =IF(K13>=(J13-M13),(IF(K13<=(I13+M13),C13,0)),0) -> 0
B14: 7 | C14: 1 | D14: C4 | E14: 长度 | F14: 15 | G14: 0.02 | H14: 0 | I14: =SUM(F14+G14) -> 15.02 | J14: =SUM(F14+H14) -> 15 | L14: =IF(K14>=(J14-M14),(IF(K14<=(I14+M14),C14,0)),0) -> 0
B15: 8 | C15: 1 | D15: D4 | E15: 长度 | F15: 94 | G15: 0.03 | H15: 0 | I15: =SUM(F15+G15) -> 94.03 | J15: =SUM(F15+H15) -> 94 | L15: =IF(K15>=(J15-M15),(IF(K15<=(I15+M15),C15,0)),0) -> 0
B16: 9 | C16: 1 | D16: B6 | E16: 长度 | F16: 10 | G16: 0 | H16: -0.02 | I16: =SUM(F16+G16) -> 10 | J16: =SUM(F16+H16) -> 9.98 | L16: =IF(K16>=(J16-M16),(IF(K16<=(I16+M16),C16,0)),0) -> 0
B17: 10 | C17: 1 | D17: B6 | E17: 直径 | F17: 22 | G17: 0.02 | H17: 0 | I17: =SUM(F17+G17) -> 22.02 | J17: =SUM(F17+H17) -> 22 | L17: =IF(K17>=(J17-M17),(IF(K17<=(I17+M17),C17,0)),0) -> 0
B18: 11 | C18: 1 | D18: B9 | E18: 长度 | F18: 80 | G18: 0 | H18: -0.03 | I18: =SUM(F18+G18) -> 80 | J18: =SUM(F18+H18) -> 79.97 | L18: =IF(K18>=(J18-M18),(IF(K18<=(I18+M18),C18,0)),0) -> 0
B19: 12 | C19: 1 | D19: B9 | E19: 长度 | F19: 40 | G19: 0.05 | H19: 0.02 | I19: =SUM(F19+G19) -> 40.05 | J19: =SUM(F19+H19) -> 40.02 | L19: =IF(K19>=(J19-M19),(IF(K19<=(I19+M19),C19,0)),0) -> 0
B20: 13 | C20: 1 | D20: C7 | E20: 直径 | F20: 10 | G20: 0.018 | H20: 0 | I20: =SUM(F20+G20) -> 10.018 | J20: =SUM(F20+H20) -> 10 | L20: =IF(K20>=(J20-M20),(IF(K20<=(I20+M20),C20,0)),0) -> 0
B21: 14 | C21: 1 | D21: D7 | E21: 直径 | F21: 20 | G21: 0 | H21: -0.02 | I21: =SUM(F21+G21) -> 20 | J21: =SUM(F21+H21) -> 19.98 | L21: =IF(K21>=(J21-M21),(IF(K21<=(I21+M21),C21,0)),0) -> 0
... B33: 26 | C33: 1 | D33: D2 | E33: 长度 | F33: 8 | G33: 0.07 | H33: 0.05 | I33: =SUM(F33+G33) -> 8.07 | J33: =SUM(F33+H33) -> 8.05 | L33: =IF(K33>=(J33-M33),(IF(K33<=(I33+M33),C33,0)),0) -> 0
I34: =SUM(F34+G34) -> 0 | J34: =SUM(F34+H34) -> 0 | L34: =IF(K34>=(J34-M34),(IF(K34<=(I34+M34),C34,0)),0) -> 0
I35: =SUM(F35+G35) -> 0 | J35: =SUM(F35+H35) -> 0 | L35: =IF(K35>=(J35-M35),(IF(K35<=(I35+M35),C35,0)),0) -> 0
I36: =SUM(F36+G36) -> 0 | J36: =SUM(F36+H36) -> 0 | L36: =IF(K36>=(J36-M36),(IF(K36<=(I36+M36),C36,0)),0) -> 0
I37: =SUM(F37+G37) -> 0 | J37: =SUM(F37+H37) -> 0 | L37: =IF(K37>=(J37-M37),(IF(K37<=(I37+M37),C37,0)),0) -> 0
I38: =SUM(F38+G38) -> 0 | J38: =SUM(F38+H38) -> 0 | L38: =IF(K38>=(J38-M38),(IF(K38<=(I38+M38),C38,0)),0) -> 0
B39: 小计 | C39: =SUM(C8:C38) -> 27 | L39: =SUM(L8:L38) -> 0
B41: B-次要尺寸
B42: 1 | C42: 1 | D42: B7 | E42: 螺纹 | F42: M30X1.5/12+2 | I42: OK | J42: NO | L42: =IF(K42=I42,(IF(K42<>J42,C42,0)),0) -> 0
B43: 2 | C43: 0.8 | D43: D8 | E43: 螺纹 | F43: M10/10+2 | I43: OK | J43: NO | L43: =IF(K43=I43,(IF(K43<>J43,C43,0)),0) -> 0
B44: 3 | C44: 0.8 | D44: D9 | E44: 螺纹 | F44: M10/10+2 | I44: OK | J44: NO | L44: =IF(K44=I44,(IF(K44<>J44,C44,0)),0) -> 0
B45: 4 | C45: 0.4 | D45: B2 | E45: 长度 | F45: 20 | G45: 0.1 | H45: -0.1 | I45: =SUM(F45+G45) -> 20.1 | J45: =SUM(F45+H45) -> 19.9 | L45: =IF(K45>=(J45-M45),(IF(K45<=(I45+M45),C45,0)),0) -> 0
B46: 5 | C46: 0.5 | D46: C3 | E46: 长度 | F46: 144 | G46: 0.1 | H46: -0.1 | I46: =SUM(F46+G46) -> 144.1 | J46: =SUM(F46+H46) -> 143.9 | L46: =IF(K46>=(J46-M46),(IF(K46<=(I46+M46),C46,0)),0) -> 0
B47: 6 | C47: 0.4 | D47: D3 | E47: 长度 | F47: 8 | G47: 0.1 | H47: -0.1 | I47: =SUM(F47+G47) -> 8.1 | J47: =SUM(F47+H47) -> 7.9 | L47: =IF(K47>=(J47-M47),(IF(K47<=(I47+M47),C47,0)),0) -> 0
B48: 7 | C48: 0.5 | D48: D4 | E48: 长度 | F48: 56 | G48: 0.1 | H48: -0.1 | I48: =SUM(F48+G48) -> 56.1 | J48: =SUM(F48+H48) -> 55.9 | L48: =IF(K48>=(J48-M48),(IF(K48<=(I48+M48),C48,0)),0) -> 0
B49: 8 | C49: 0.4 | D49: C4 | E49: 长度 | F49: 13 | G49: 0.1 | H49: -0.1 | I49: =SUM(F49+G49) -> 13.1 | J49: =SUM(F49+H49) -> 12.9 | L49: =IF(K49>=(J49-M49),(IF(K49<=(I49+M49),C49,0)),0) -> 0
B50: 9 | C50: 0.4 | D50: A5 | E50: 长度 | F50: 15 | G50: 0.1 | H50: -0.1 | I50: =SUM(F50+G50) -> 15.1 | J50: =SUM(F50+H50) -> 14.9 | L50: =IF(K50>=(J50-M50),(IF(K50<=(I50+M50),C50,0)),0) -> 0
B51: 10 | C51: 0.4 | D51: A5 | E51: 长度 | F51: 48 | G51: 0.1 | H51: -0.1 | I51: =SUM(F51+G51) -> 48.1 | J51: =SUM(F51+H51) -> 47.9 | L51: =IF(K51>=(J51-M51),(IF(K51<=(I51+M51),C51,0)),0) -> 0
B52: 11 | C52: 0.4 | D52: B5 | E52: 长度 | F52: 15 | G52: 0.1 | H52: -0.1 | I52: =SUM(F52+G52) -> 15.1 | J52: =SUM(F52+H52) -> 14.9 | L52: =IF(K52>=(J52-M52),(IF(K52<=(I52+M52),C52,0)),0) -> 0
B53: 12 | C53: 0.4 | D53: D7 | E53: 长度 | F53: 6 | G53: 0.1 | H53: -0.1 | I53: =SUM(F53+G53) -> 6.1 | J53: =SUM(F53+H53) -> 5.9 | L53: =IF(K53>=(J53-M53),(IF(K53<=(I53+M53),C53,0)),0) -> 0
B54: 13 | C54: 0.4 | D54: C9 | E54: 长度 | F54: 30 | G54: 0.1 | H54: -0.1 | I54: =SUM(F54+G54) -> 30.1 | J54: =SUM(F54+H54) -> 29.9 | L54: =IF(K54>=(J54-M54),(IF(K54<=(I54+M54),C54,0)),0) -> 0
...
